Workbook

Sheet Holdings
B2: =_xlfn.XLOOKUP(B3,Mapping!$C:$C,Mapping!$D:$D) -> #N/A | C2: =_xlfn.XLOOKUP(C3,Mapping!$C:$C,Mapping!$D:$D) -> #N/A | D2: =_xlfn.XLOOKUP(D3,Mapping!$C:$C,Mapping!$D:$D) -> #N/A | E2: =_xlfn.XLOOKUP(E3,Mapping!$C:$C,Mapping!$D:$D) -> #N/A | F2: =_xlfn.XLOOKUP(F3,Mapping!$C:$C,Mapping!$D:$D) -> Reporting Date | G2: =_xlfn.XLOOKUP(G3,Mapping!$C:$C,Mapping!$D:$D) -> Model Portfolio | H2: =_xlfn.XLOOKUP(H3,Mapping!$C:$C,Mapping!$D:$D) -> Portfolio | I2: =_xlfn.XLOOKUP(I3,Mapping!$C:$C,Mapping!$D:$D) -> Security ID | ... GA2: =_xlfn.XLOOKUP(GA3,Mapping!$C:$C,Mapping!$D:$D) -> #N/A
B3: Unique Identifier | C3: Investor Code | D3: Identification ID | E3: Code Name | F3: Reporting Date | G3: Model Portfolio | H3: Portfolio | I3: Security ID | J3: Security Name | K3: Portfolio Name | L3: Model Portfolio Name | M3: Portfolio Group | N3: Current Underlying Amount PC | O3: Current Underlying Amount RC | P3: Portfolio Currency | Q3: Security Type Name | R3: RA_Bullet | S3: Loan Code | T3: Asset Type RA | U3: RA Country | V3: RA Asset Country Name | W3: Underlying Asset Type | X3: CRDB Code | Y3: WAL | Z3: Quotation Currency | AA3: FX Rate EC | AB3: Forex | AC3: Initial Commitment Amount CCY | AD3: Gross Notional PC | AE3: Gross Notional RC | AF3: Balance Funded % | AG3: Balance Book Value PC | AH3: Balance Nominal/Number | AI3: Balance Unfunded Amount | AJ3: RA_Commitment QC | AK3: Current Drawn Amount CCY | AL3: Current Drawn Amount PC | AM3: RA_Referentiel Rate | AN3: Yield | AO3: Yield EUR | AP3: Yield GBP | AQ3: Purchase Price % | AR3: Clean Price for Weight | AS3: Purchase Date | AT3: Maturity Date | AU3: Next Coupon Date Format | AV3: Parent Issuer ID | AW3: Parent Issuer Name | AX3: RA_Listed Borrower | AY3: Issuer Name | AZ3: Issuer | BA3: Issuer Country | BB3: Group Name | BC3: LEI | BD3: TAB Status | BE3: CR Status | BF3: CR Limit | BG3: Current NDS | BH3: Underlying Parent Issuer ID | BI3: RA Commitment PC | BJ3: RA Commitment RC | BK3: Rate Type | BL3: Seniority | BM3: STEF Level | BN3: Modified Duration YTM | BO3: Time to Maturity | BP3: RA_Floored | BQ3: Make Whole Case | BR3: Nature | BS3: RA Ident | BT3: FM Controller Infra | BU3: FMCG Controller | BV3: Next Rate (Index) | BW3: Interest Payment Frequency | BX3: Basis | BY3: All-in Spread at Acquisition | BZ3: Spread | CA3: Next Coupon | CB3: Index | CC3: Internal Current Rating | CD3: Ext Sec Group_Rating_Closing | CE3: Rating Fitch | CF3: Rating S&P | CG3: Rating Moody's | CH3: Last Compliance Certification Date | CI3: ICR Limit | CJ3: ICR Current | CK3: ICR Day One | CL3: ICR Status | CM3: ICR Trend | CN3: ICR -3m | CO3: ICR -6m | CP3: ICR -9m | CQ3: ICR -1y | CR3: ICR -2y | CS3: LLCR Cash Trap | CT3: LLCR Covenant (RA) | CU3: LLCR Status | CV3: LTV -3m | CW3: LTV -6m | CX3: LTV -9m | CY3: LTV -1y | CZ3: LTV -2y | DA3: LTV Current | DB3: LTV Day One | DC3: LTV Limit | DD3: LTV Status | DE3: LTV Trend | DF3: LEV Cash Trap | DG3: LEV Limit | DH3: LEV Status | DI3: RA_LVG_D1 | DJ3: RA_COD_LVG | DK3: RA_NDRAB_CT | DL3: RA_COD_NDRAB | DM3: RA_DSC_D1 | DN3: RA_COD_DSC | DO3: PLCR Cash Trap | DP3: Cash Trap LTV Covenant | DQ3: Cash Trap ICR Covenant | DR3: Cash Trap DY Covenant | DS3: NAH Cash Trap | DT3: NDS Cash Trap | DU3: GR Cash Trap | DV3: CR Cash Trap | DW3: RA_CR_D1 | DX3: RA_ICR_D1 | DY3: RA_COD_ICR | DZ3: RA_COD_CR | EA3: PLCR Status | EB3: PLCR Covenant (RA) | EC3: DSC Trans | ED3: DSC Status | EE3: DSC Limit | EF3: DSC Cash Trap | EG3: RA_DC_CT | EH3: RA_DC_COV | EI3: DSC Day One | EJ3: DSC -3m | EK3: DSC -6m | EL3: DSC -9m | EM3: DSC -1y | EN3: DSC -2y | EO3: RA_COD_DC | EP3: DC Status | EQ3: RA_COD_DY | ER3: DY Trend | ES3: DY Status | ET3: DY Limit | EU3: RA_DY_D1 | EV3: DY -3m | EW3: DY -6m | EX3: DY -9m | EY3: DY -1y | EZ3: DY -2y | FA3: GR Status | FB3: GR Covenant | FC3: RA_LTV_D1 | FD3: RA_Infra Risk Profile | FE3: RA_Infra Rating | FF3: RA_COD_LTV | FG3: NAH Status | FH3: NAH Covenants | FI3: Current NAH | FJ3: NDS Status | FK3: NDS Covenant | FL3: Current FAV | FM3: Current PLCR (RA) | FN3: Current LLCR (RA) | FO3: Revenue -1y | FP3: Revenue -2y | FQ3: RA EBITDA | FR3: EBITDA -1y | FS3: EBITDA -2y | FT3: FO_RA_LTV Covenant | FU3: FO_RA_ICR Covenant | FV3: FO_RA_Current ICR | FW3: FO_RA_Current LTV | FX3: RA Revenue | FY3: FAV Cash Trap | FZ3: FAV Covenant | GA3: FAV Status
B4: =C4&"x"&I4 -> 61024x100200 | C4: =IF(G4="SINGLE",H4,G4) -> 61024 | D4: =_xlfn.XLOOKUP(I4,calculations!$t:$t,calculations!$s:$s) -> #VALUE! | E4: =_xlfn.XLOOKUP(I4,Mapping!$T:$T,Mapping!$Q:$Q) -> AURO01 | F4: 46203 | G4: 61024 | H4: 61024 | I4: 100200 | J4: Aurora Offshore | K4: Fund 4 Fund | L4: Fund 4 Fund | M4: Infra Debt | N4: 12462000 | O4: 12462000 | P4: EUR | Q4: Private Placement Note | R4: N | S4: L100200 | T4: Infrastructure Debt | U4: DE | V4: Germany | W4: Offshore wind | X4: CR1000 | Y4: 8.9 | Z4: EUR | AA4: 1 | AB4: N | AC4: 29748000 | AD4: 29748000 | AE4: 29748000 | AF4: 0.4189 | AG4: 12462000 | AH4: 12462000 | AI4: 17286000 | AJ4: 29748000 | AK4: 12462000 | AL4: 12462000 | AM4: EURIBOR 6M | AN4: 5.277 | AO4: 3.811 | AP4: 5.693 | AQ4: 100 | AR4: 100 | AS4: 42349 | AT4: 46915 | AU4: 46295 | AV4: PI2000 | AW4: Corvus Digital | AX4: N | AY4: Aurora Offshore Finance Ltd | AZ4: Aurora Offshore Finance | BA4: Germany | BB4: Corvus Digital | BC4: 529900SYNTH000000000 | BI4: 29748000 | BJ4: 29748000 | BK4: Floating | BL4: Senior Secured | BN4: 7.5 | BO4: 1.95 | BP4: Y | BQ4: N | BR4: Debt | BS4: RA100200 | BT4: E. Rossi | BU4: E. Rossi | BW4: Semi-annual | BX4: ACT/360 | BY4: 165 | BZ4: 165 | CB4: EURIBOR | CC4: BBB | CD4: BBB | CE4: BBB+ | CF4: BBB+ | CG4: NR | CH4: 46112 | CI4: 1.2 | CJ4: 2.43 | CK4: 2.55 | CL4: OK | DA4: 0.8 | DC4: 0.85 | DD4: Watch | ED4: OK | EE4: 1.05 | EI4: 1.48 | FQ4: 53363427
B5: =C5&"x"&I5 -> 61021x100200 | C5: =IF(G5="SINGLE",H5,G5) -> 61021 | D5: =_xlfn.XLOOKUP(I5,calculations!$t:$t,calculations!$s:$s) -> #VALUE! | E5: =_xlfn.XLOOKUP(I5,Mapping!$T:$T,Mapping!$Q:$Q) -> AURO01 | F5: 46203 | G5: 61021 | H5: 61021 | I5: 100200 | J5: Aurora Offshore | K5: Fund 1 Fund | L5: Fund 1 Fund | M5: Infra Debt | N5: 24863000 | O5: 24863000 | P5: EUR | Q5: Private Placement Note | R5: N | S5: L100200 | T5: Infrastructure Debt | U5: DE | V5: Germany | W5: Offshore wind | X5: CR1000 | Y5: 8.9 | Z5: EUR | AA5: 1 | AB5: N | AC5: 59352000 | AD5: 59352000 | AE5: 59352000 | AF5: 0.4189 | AG5: 24863000 | AH5: 24863000 | AI5: 34489000 | AJ5: 59352000 | AK5: 24863000 | AL5: 24863000 | AM5: EURIBOR 6M | AN5: 3.212 | AO5: 6.46 | AP5: 2.809 | AQ5: 100 | AR5: 100 | AS5: 42349 | AT5: 46915 | AU5: 46295 | AV5: PI2000 | AW5: Corvus Digital | AX5: N | AY5: Aurora Offshore Finance Ltd | AZ5: Aurora Offshore Finance | BA5: Germany | BB5: Corvus Digital | BC5: 529900SYNTH000000000 | BI5: 59352000 | BJ5: 59352000 | BK5: Floating | BL5: Senior Secured | BN5: 7.5 | BO5: 1.95 | BP5: Y | BQ5: N | BR5: Debt | BS5: RA100200 | BT5: E. Rossi | BU5: E. Rossi | BW5: Semi-annual | BX5: ACT/360 | BY5: 165 | BZ5: 165 | CB5: EURIBOR | CC5: BBB | CD5: BBB | CE5: BBB+ | CF5: BBB+ | CG5: NR | CH5: 46112 | CI5: 1.2 | CJ5: 2.29 | CK5: 2.4 | CL5: OK | DA5: 0.72 | DC5: 0.85 | DD5: OK | ED5: OK | EE5: 1.05 | EI5: 1.35 | FQ5: 83702383
B6: =C6&"x"&I6 -> 61015x100200 | C6: =IF(G6="SINGLE",H6,G6) -> 61015 | D6: =_xlfn.XLOOKUP(I6,calculations!$t:$t,calculations!$s:$s) -> #VALUE! | E6: =_xlfn.XLOOKUP(I6,Mapping!$T:$T,Mapping!$Q:$Q) -> AURO01 | F6: 46203 | G6: 61015 | H6: 61015 | I6: 100200 | J6: Aurora Offshore | K6: Investor 15 Mandate | L6: Investor 15 Mandate | M6: Infra Debt | N6: 13726000 | O6: 13726000 | P6: EUR | Q6: Private Placement Note | R6: N | S6: L100200 | T6: Infrastructure Debt | U6: DE | V6: Germany | W6: Offshore wind | X6: CR1000 | Y6: 8.9 | Z6: EUR | AA6: 1 | AB6: N | AC6: 32765000 | AD6: 32765000 | AE6: 32765000 | AF6: 0.4189 | AG6: 13726000 | AH6: 13726000 | AI6: 19039000 | AJ6: 32765000 | AK6: 13726000 | AL6: 13726000 | AM6: EURIBOR 6M | AN6: 2.908 | AO6: 4.526 | AP6: 6.012 | AQ6: 100 | AR6: 100 | AS6: 42349 | AT6: 46915 | AU6: 46295 | AV6: PI2000 | AW6: Corvus Digital | AX6: N | AY6: Aurora Offshore Finance Ltd | AZ6: Aurora Offshore Finance | BA6: Germany | BB6: Corvus Digital | BC6: 529900SYNTH000000000 | BI6: 32765000 | BJ6: 32765000 | BK6: Floating | BL6: Senior Secured | BN6: 7.5 | BO6: 1.95 | BP6: Y | BQ6: N | BR6: Debt | BS6: RA100200 | BT6: E. Rossi | BU6: D. Schäfer | BW6: Semi-annual | BX6: 30/360 | BY6: 165 | BZ6: 165 | CB6: EURIBOR | CC6: BBB | CD6: BBB | CE6: BBB+ | CF6: BBB+ | CG6: NR | CH6: 46112 | CI6: 1.2 | CJ6: 2.91 | CK6: 3.06 | CL6: OK | DA6: 0.79 | DC6: 0.85 | DD6: OK | ED6: Watch | EE6: 1.05 | EI6: 1.11 | FQ6: 62586420
B7: =C7&"x"&I7 -> 61007x100200 | C7: =IF(G7="SINGLE",H7,G7) -> 61007 | D7: =_xlfn.XLOOKUP(I7,calculations!$t:$t,calculations!$s:$s) -> #VALUE! | E7: =_xlfn.XLOOKUP(I7,Mapping!$T:$T,Mapping!$Q:$Q) -> AURO01 | F7: 46203 | G7: 61007 | H7: 61007 | I7: 100200 | J7: Aurora Offshore | K7: Investor 7 Portfolio | L7: Investor 7 Portfolio | M7: Infra Debt | N7: 23915000 | O7: 23915000 | P7: GBP | Q7: Private Placement Note | R7: N | S7: L100200 | T7: Infrastructure Debt | U7: DE | V7: Germany | W7: Offshore wind | X7: CR1000 | Y7: 8.9 | Z7: EUR | AA7: 1 | AB7: N | AC7: 57089000 | AD7: 57089000 | AE7: 57089000 | AF7: 0.4189 | AG7: 23915000 | AH7: 23915000 | AI7: 33174000 | AJ7: 57089000 | AK7: 23915000 | AL7: 23915000 | AM7: EURIBOR 6M | AN7: 4.386 | AO7: 4.368 | AP7: 5.244 | AQ7: 100 | AR7: 100 | AS7: 42349 | AT7: 46915 | AU7: 46295 | AV7: PI2000 | AW7: Corvus Digital | AX7: N | AY7: Aurora Offshore Finance Ltd | AZ7: Aurora Offshore Finance | BA7: Germany | BB7: Corvus Digital | BC7: 529900SYNTH000000000 | BI7: 57089000 | BJ7: 57089000 | BK7: Floating | BL7: Senior Secured | BN7: 7.5 | BO7: 1.95 | BP7: Y | BQ7: N | BR7: Debt | BS7: RA100200 | BT7: E. Rossi | BU7: B. Okoro | BW7: Semi-annual | BX7: 30/360 | BY7: 165 | BZ7: 165 | CB7: EURIBOR | CC7: BBB | CD7: BBB | CE7: BBB+ | CF7: BBB+ | CG7: NR | CH7: 46112 | CI7: 1.2 | CJ7: 1.78 | CK7: 1.87 | CL7: OK | DA7: 0.7 | DC7: 0.85 | DD7: OK | ED7: Watch | EE7: 1.05 | EI7: 1.1 | FQ7: 58695684
B8: =C8&"x"&I8 -> 61023x100200 | C8: =IF(G8="SINGLE",H8,G8) -> 61023 | D8: =_xlfn.XLOOKUP(I8,calculations!$t:$t,calculations!$s:$s) -> #VALUE! | E8: =_xlfn.XLOOKUP(I8,Mapping!$T:$T,Mapping!$Q:$Q) -> AURO01 | F8: 46203 | G8: 61023 | H8: 61023 | I8: 100200 | J8: Aurora Offshore | K8: Fund 3 Fund | L8: Fund 3 Fund | M8: Infra Debt | N8: 38584000 | O8: 38584000 | P8: EUR | Q8: Private Placement Note | R8: N | S8: L100200 | T8: Infrastructure Debt | U8: DE | V8: Germany | W8: Offshore wind | X8: CR1000 | Y8: 8.9 | Z8: EUR | AA8: 1 | AB8: N | AC8: 92104000 | AD8: 92104000 | AE8: 92104000 | AF8: 0.4189 | AG8: 38584000 | AH8: 38584000 | AI8: 53520000 | AJ8: 92104000 | AK8: 38584000 | AL8: 38584000 | AM8: EURIBOR 6M | AN8: 3.204 | AO8: 2.599 | AP8: 3.73 | AQ8: 100 | AR8: 100 | AS8: 42349 | AT8: 46915 | AU8: 46295 | AV8: PI2000 | AW8: Corvus Digital | AX8: N | AY8: Aurora Offshore Finance Ltd | AZ8: Aurora Offshore Finance | BA8: Germany | BB8: Corvus Digital | BC8: 529900SYNTH000000000 | BI8: 92104000 | BJ8: 92104000 | BK8: Floating | BL8: Senior Secured | BN8: 7.5 | BO8: 1.95 | BP8: Y | BQ8: N | BR8: Debt | BS8: RA100200 | BT8: E. Rossi | BU8: B. Okoro | BW8: Semi-annual | BX8: 30/360 | BY8: 165 | BZ8: 165 | CB8: EURIBOR | CC8: BBB | CD8: BBB | CE8: BBB+ | CF8: BBB+ | CG8: NR | CH8: 46112 | CI8: 1.2 | CJ8: 2.86 | CK8: 3 | CL8: OK | DA8: 0.81 | DC8: 0.85 | DD8: Watch | ED8: OK | EE8: 1.05 | EI8: 1.34 | FQ8: 69307283
B9: =C9&"x"&I9 -> 61003x100200 | C9: =IF(G9="SINGLE",H9,G9) -> 61003 | D9: =_xlfn.XLOOKUP(I9,calculations!$t:$t,calculations!$s:$s) -> #VALUE! | E9: =_xlfn.XLOOKUP(I9,Mapping!$T:$T,Mapping!$Q:$Q) -> AURO01 | F9: 46203 | G9: SINGLE | H9: 61003 | I9: 100200 | J9: Aurora Offshore | K9: Investor 19 Mandate | L9: Investor 19 Mandate | M9: Infra Debt | N9: 14535000 | O9: 14535000 | P9: EUR | Q9: Private Placement Note | R9: N | S9: L100200 | T9: Infrastructure Debt | U9: DE | V9: Germany | W9: Offshore wind | X9: CR1000 | Y9: 8.9 | Z9: EUR | AA9: 1 | AB9: N | AC9: 34696000 | AD9: 34696000 | AE9: 34696000 | AF9: 0.4189 | AG9: 14535000 | AH9: 14535000 | AI9: 20161000 | AJ9: 34696000 | AK9: 14535000 | AL9: 14535000 | AM9: EURIBOR 6M | AN9: 2.597 | AO9: 3.69 | AP9: 6.314 | AQ9: 100 | AR9: 100 | AS9: 42349 | AT9: 46915 | AU9: 46295 | AV9: PI2000 | AW9: Corvus Digital | AX9: N | AY9: Aurora Offshore Finance Ltd | AZ9: Aurora Offshore Finance | BA9: Germany | BB9: Corvus Digital | BC9: 529900SYNTH000000000 | BI9: 34696000 | BJ9: 34696000 | BK9: Floating | BL9: Senior Secured | BN9: 7.5 | BO9: 1.95 | BP9: Y | BQ9: N | BR9: Debt | BS9: RA100200 | BT9: E. Rossi | BU9: F. Lindqvist | BW9: Semi-annual | BX9: 30/360 | BY9: 165 | BZ9: 165 | CB9: EURIBOR | CC9: BBB | CD9: BBB | CE9: BBB+ | CF9: BBB+ | CG9: NR | CH9: 46112 | CI9: 1.2 | CJ9: 3.26 | CK9: 3.42 | CL9: OK | DA9: 0.48 | DC9: 0.85 | DD9: OK | ED9: OK | EE9: 1.05 | EI9: 1.55 | FQ9: 74889817
B10: =C10&"x"&I10 -> 61003x100201 | C10: =IF(G10="SINGLE",H10,G10) -> 61003 | D10: =_xlfn.XLOOKUP(I10,calculations!$t:$t,calculations!$s:$s) -> #VALUE! | E10: =_xlfn.XLOOKUP(I10,Mapping!$T:$T,Mapping!$Q:$Q) -> BEAC02 | F10: 46203 | G10: 61003 | H10: 61003 | I10: 100201 | J10: Beacon Airports | K10: Investor 3 Portfolio | L10: Investor 3 Portfolio | M10: Infra Debt | N10: 57363000 | O10: 67091228 | P10: EUR | Q10: Loan | R10: Y | S10: L100201 | T10: Infrastructure Debt | U10: GB | V10: United Kingdom | W10: Airports | X10: CR1001 | Y10: 10.5 | Z10: GBP | AA10: 0.855 | AB10: Y | AC10: 143610000 | AD10: 136771000 | AE10: 1.5996608e+08 | AF10: 0.4194 | AG10: 57363000 | AH10: 57363000 | AI10: 79408000 | AJ10: 136771000 | AK10: 57363000 | AL10: 57363000 | AM10: EURIBOR 6M | AN10: 3.228 | AO10: 3.234 | AP10: 4.545 | AQ10: 100 | AR10: 100 | AS10: 45048 | AT10: 50346 | AU10: 46295 | AV10: PI2001 | AW10: Aquila Utilities | AX10: N | AY10: Beacon Airports Finance Ltd | AZ10: Beacon Airports Finance | BA10: United Kingdom | BB10: Aquila Utilities | BC10: 529900SYNTH000000001 | BI10: 136771000 | BJ10: 1.5996608e+08 | BK10: Floating | BL10: Senior Secured | BN10: 8.7 | BO10: 11.34 | BP10: Y | BQ10: N | BR10: Debt | BS10: RA100201 | BT10: E. Rossi | BU10: B. Okoro | BW10: Semi-annual | BX10: 30/360 | BY10: 345 | BZ10: 345 | CB10: EURIBOR | CC10: BBB- | CD10: BBB- | CE10: BBB | CF10: NR | CG10: Baa2 | CH10: 46112 | CI10: 1.2 | CJ10: 1.93 | CK10: 2.03 | CL10: OK | DA10: 0.72 | DC10: 0.85 | DD10: OK | ED10: OK | EE10: 1.05 | EI10: 1.48 | FQ10: 74758575
B11: =C11&"x"&I11 -> 61014x100201 | C11: =IF(G11="SINGLE",H11,G11) -> 61014 | D11: =_xlfn.XLOOKUP(I11,calculations!$t:$t,calculations!$s:$s) -> #VALUE! | E11: =_xlfn.XLOOKUP(I11,Mapping!$T:$T,Mapping!$Q:$Q) -> BEAC02 | F11: 46203 | G11: 61014 | H11: 61014 | I11: 100201 | J11: Beacon Airports | K11: Investor 14 Mandate | L11: Investor 14 Mandate | M11: Infra Debt | N11: 113600000 | O11: 1.328655e+08 | P11: EUR | Q11: Loan | R11: Y | S11: L100201 | T11: Infrastructure Debt | U11: GB | V11: United Kingdom | W11: Airports | X11: CR1001 | Y11: 10.5 | Z11: GBP | AA11: 0.855 | AB11: Y | AC11: 284399000 | AD11: 270856000 | AE11: 3.1679064e+08 | AF11: 0.4194 | AG11: 113600000 | AH11: 113600000 | AI11: 157256000 | AJ11: 270856000 | AK11: 113600000 | AL11: 113600000 | AM11: EURIBOR 6M | AN11: 6.226 | AO11: 5.616 | AP11: 3.178 | AQ11: 100 | AR11: 100 | AS11: 45048 | AT11: 50346 | AU11: 46295 | AV11: PI2001 | AW11: Aquila Utilities | AX11: N | AY11: Beacon Airports Finance Ltd | AZ11: Beacon Airports Finance | BA11: United Kingdom | BB11: Aquila Utilities | BC11: 529900SYNTH000000001 | BI11: 270856000 | BJ11: 3.1679064e+08 | BK11: Floating | BL11: Senior Secured | BN11: 8.7 | BO11: 11.34 | BP11: Y | BQ11: N | BR11: Debt | BS11: RA100201 | BT11: E. Rossi | BU11: F. Lindqvist | BW11: Semi-annual | BX11: 30/360 | BY11: 345 | BZ11: 345 | CB11: EURIBOR | CC11: BBB- | CD11: BBB- | CE11: BBB | CF11: NR | CG11: Baa2 | CH11: 46112 | CI11: 1.2 | CJ11: 2.62 | CK11: 2.75 | CL11: OK | DA11: 0.69 | DC11: 0.85 | DD11: OK | ED11: OK | EE11: 1.05 | EI11: 1.49 | FQ11: 104056878
B12: =C12&"x"&I12 -> 61009x100202 | C12: =IF(G12="SINGLE",H12,G12) -> 61009 | D12: =_xlfn.XLOOKUP(I12,calculations!$t:$t,calculations!$s:$s) -> #VALUE! | E12: =_xlfn.XLOOKUP(I12,Mapping!$T:$T,Mapping!$Q:$Q) -> CASC03 | F12: 46203 | G12: 61009 | H12: 61009 | I12: 100202 | J12: Cascade Telecom | K12: Investor 9 Portfolio | L12: Investor 9 Portfolio | M12: Infra Debt | N12: 69543000 | O12: 69543000 | P12: USD | Q12: Loan | R12: N | S12: L100202 | T12: Infrastructure Debt | U12: DE | V12: Germany | W12: Telecom towers | X12: CR1002 | Y12: 12.6 | Z12: EUR | AA12: 1 | AB12: N | AC12: 72504000 | AD12: 72504000 | AE12: 72504000 | AF12: 0.9592 | AG12: 69543000 | AH12: 69543000 | AI12: 2961000 | AJ12: 72504000 | AK12: 69543000 | AL12: 69543000 | AN12: 3.671 | AO12: 5.067 | AP12: 3.783 | AQ12: 100 | AR12: 100 | AS12: 43414 | AT12: 51631 | AU12: 46295 | AV12: PI2002 | AW12: Silverline Transport | AX12: N | AY12: Cascade Telecom Finance Ltd | AZ12: Cascade Telecom Finance | BA12: Germany | BB12: Silverline Transport | BC12: 529900SYNTH000000002 | BI12: 72504000 | BJ12: 72504000 | BK12: Fixed | BL12: Senior Secured | BN12: 13.5 | BO12: 14.86 | BP12: N | BQ12: N | BR12: Debt | BS12: RA100202 | BT12: C. Dubois | BU12: F. Lindqvist | BW12: Semi-annual | BX12: 30/360 | BY12: 255 | BZ12: 255 | CC12: A | CD12: A | CE12: NR | CF12: NR | CG12: NR | CH12: 46112 | CI12: 1.2 | CJ12: 1.54 | CK12: 1.62 | CL12: OK | DA12: 0.8 | DC12: 0.85 | DD12: Watch | ED12: OK | EE12: 1.05 | EI12: 1.6 | FQ12: 58262138
B13: =C13&"x"&I13 -> 61014x100202 | C13: =IF(G13="SINGLE",H13,G13) -> 61014 | D13: =_xlfn.XLOOKUP(I13,calculations!$t:$t,calculations!$s:$s) -> #VALUE! | E13: =_xlfn.XLOOKUP(I13,Mapping!$T:$T,Mapping!$Q:$Q) -> CASC03 | F13: 46203 | G13: 61014 | H13: 61014 | I13: 100202 | J13: Cascade Telecom | K13: Investor 14 Mandate | L13: Investor 14 Mandate | M13: Infra Debt | N13: 84027000 | O13: 84027000 | P13: EUR | Q13: Loan | R13: N | S13: L100202 | T13: Infrastructure Debt | U13: DE | V13: Germany | W13: Telecom towers | X13: CR1002 | Y13: 12.6 | Z13: EUR | AA13: 1 | AB13: N | AC13: 87604000 | AD13: 87604000 | AE13: 87604000 | AF13: 0.9592 | AG13: 84027000 | AH13: 84027000 | AI13: 3577000 | AJ13: 87604000 | AK13: 84027000 | AL13: 84027000 | AN13: 6.402 | AO13: 6.252 | AP13: 5.575 | AQ13: 100 | AR13: 100 | AS13: 43414 | AT13: 51631 | AU13: 46295 | AV13: PI2002 | AW13: Silverline Transport | AX13: N | AY13: Cascade Telecom Finance Ltd | AZ13: Cascade Telecom Finance | BA13: Germany | BB13: Silverline Transport | BC13: 529900SYNTH000000002 | BI13: 87604000 | BJ13: 87604000 | BK13: Fixed | BL13: Senior Secured | BN13: 13.5 | BO13: 14.86 | BP13: N | BQ13: N | BR13: Debt | BS13: RA100202 | BT13: C. Dubois | BU13: F. Lindqvist | BW13: Semi-annual | BX13: ACT/360 | BY13: 255 | BZ13: 255 | CC13: A | CD13: A | CE13: NR | CF13: NR | CG13: NR | CH13: 46112 | CI13: 1.2 | CJ13: 2.14 | CK13: 2.25 | CL13: OK | DA13: 0.69 | DC13: 0.85 | DD13: OK | ED13: OK | EE13: 1.05 | EI13: 1.94 | FQ13: 56598815
B14: =C14&"x"&I14 -> 61019x100202 | C14: =IF(G14="SINGLE",H14,G14) -> 61019 | D14: =_xlfn.XLOOKUP(I14,calculations!$t:$t,calculations!$s:$s) -> #VALUE! | E14: =_xlfn.XLOOKUP(I14,Mapping!$T:$T,Mapping!$Q:$Q) -> CASC03 | F14: 46203 | G14: 61019 | H14: 61019 | I14: 100202 | J14: Cascade Telecom | K14: Investor 19 Mandate | L14: Investor 19 Mandate | M14: Infra Debt | N14: 64963000 | O14: 64963000 | P14: EUR | Q14: Loan | R14: N | S14: L100202 | T14: Infrastructure Debt | U14: DE | V14: Germany | W14: Telecom towers | X14: CR1002 | Y14: 12.6 | Z14: EUR | AA14: 1 | AB14: N | AC14: 67729000 | AD14: 67729000 | AE14: 67729000 | AF14: 0.9592 | AG14: 64963000 | AH14: 64963000 | AI14: 2766000 | AJ14: 67729000 | AK14: 64963000 | AL14: 64963000 | AN14: 3.926 | AO14: 2.913 | AP14: 5.202 | AQ14: 100 | AR14: 100 | AS14: 43414 | AT14: 51631 | AU14: 46295 | AV14: PI2002 | AW14: Silverline Transport | AX14: N | AY14: Cascade Telecom Finance Ltd | AZ14: Cascade Telecom Finance | BA14: Germany | BB14: Silverline Transport | BC14: 529900SYNTH000000002 | BI14: 67729000 | BJ14: 67729000 | BK14: Fixed | BL14: Senior Secured | BN14: 13.5 | BO14: 14.86 | BP14: N | BQ14: N | BR14: Debt | BS14: RA100202 | BT14: C. Dubois | BU14: C. Dubois | BW14: Quarterly | BX14: ACT/360 | BY14: 255 | BZ14: 255 | CC14: A | CD14: A | CE14: NR | CF14: NR | CG14: NR | CH14: 46112 | CI14: 1.2 | CJ14: 1.62 | CK14: 1.7 | CL14: OK | DA14: 0.56 | DC14: 0.85 | DD14: OK | ED14: OK | EE14: 1.05 | EI14: 1.23 | FQ14: 60658550
B15: =C15&"x"&I15 -> 61018x100202 | C15: =IF(G15="SINGLE",H15,G15) -> 61018 | D15: =_xlfn.XLOOKUP(I15,calculations!$t:$t,calculations!$s:$s) -> #VALUE! | E15: =_xlfn.XLOOKUP(I15,Mapping!$T:$T,Mapping!$Q:$Q) -> CASC03 | F15: 46203 | G15: 61018 | H15: 61018 | I15: 100202 | J15: Cascade Telecom | K15: Investor 18 Mandate | L15: Investor 18 Mandate | M15: Infra Debt | N15: 25434000 | O15: 25434000 | P15: EUR | Q15: Loan | R15: N | S15: L100202 | T15: Infrastructure Debt | U15: DE | V15: Germany | W15: Telecom towers | X15: CR1002 | Y15: 12.6 | Z15: EUR | AA15: 1 | AB15: N | AC15: 26517000 | AD15: 26517000 | AE15: 26517000 | AF15: 0.9592 | AG15: 25434000 | AH15: 25434000 | AI15: 1083000 | AJ15: 26517000 | AK15: 25434000 | AL15: 25434000 | AN15: 5.354 | AO15: 5.699 | AP15: 5.276 | AQ15: 100 | AR15: 100 | AS15: 43414 | AT15: 51631 | AU15: 46295 | AV15: PI2002 | AW15: Silverline Transport | AX15: N | AY15: Cascade Telecom Finance Ltd | AZ15: Cascade Telecom Finance | BA15: Germany | BB15: Silverline Transport | BC15: 529900SYNTH000000002 | BI15: 26517000 | BJ15: 26517000 | BK15: Fixed | BL15: Senior Secured | BN15: 13.5 | BO15: 14.86 | BP15: N | BQ15: N | BR15: Debt | BS15: RA100202 | BT15: C. Dubois | BU15: C. Dubois | BW15: Quarterly | BX15: ACT/360 | BY15: 255 | BZ15: 255 | CC15: A | CD15: A | CE15: NR | CF15: NR | CG15: NR | CH15: 46112 | CI15: 1.2 | CJ15: 2.87 | CK15: 3.01 | CL15: OK | DA15: 0.71 | DC15: 0.85 | DD15: OK | ED15: Watch | EE15: 1.05 | EI15: 1.18 | FQ15: 59484021
B16: =C16&"x"&I16 -> 61013x100203 | C16: =IF(G16="SINGLE",H16,G16) -> 61013 | D16: =_xlfn.XLOOKUP(I16,calculations!$t:$t,calculations!$s:$s) -> #VALUE! | E16: =_xlfn.XLOOKUP(I16,Mapping!$T:$T,Mapping!$Q:$Q) -> DELT04 | F16: 46203 | G16: 61013 | H16: 61013 | I16: 100203 | J16: Delta Water A | K16: Investor 13 Mandate | L16: Investor 13 Mandate | M16: Infra Debt | N16: 447000 | O16: 522807.02 | P16: EUR | Q16: Private Placement Note | R16: N | S16: L100203 | T16: Infrastructure Debt | U16: GB | V16: United Kingdom | W16: Water | X16: CR1003 | Y16: 14.2 | Z16: GBP | AA16: 0.855 | AB16: Y | AC16: 858000 | AD16: 858000 | AE16: 1003508.8 | AF16: 0.521 | AG16: 447000 | AH16: 447000 | AI16: 411000 | AJ16: 858000 | AK16: 447000 | AL16: 447000 | AN16: 5.084 | AO16: 5.506 | AP16: 4.799 | AQ16: 100 | AR16: 100 | AS16: 44791 | AT16: 54288 | AU16: 46295 | AV16: PI2003 | AW16: Corvus Digital | AX16: N | AY16: Delta Water Finance Ltd | AZ16: Delta Water Finance | BA16: United Kingdom | BB16: Corvus Digital | BC16: 529900SYNTH000000003 | BI16: 858000 | BJ16: 1003508.8 | BK16: Fixed | BL16: Senior Secured | BN16: 15.6 | BO16: 22.14 | BP16: N | BQ16: N | BR16: Debt | BS16: RA100203 | BT16: A. Martin | BU16: D. Schäfer | BW16: Semi-annual | BX16: 30/360 | BY16: 325 | BZ16: 325 | CC16: BBB+ | CD16: BBB+ | CE16: NR | CF16: NR | CG16: NR | CH16: 46112 | CI16: 1.2 | CJ16: 2.09 | CK16: 2.19 | CL16: OK | DA16: 0.49 | DC16: 0.85 | DD16: OK | ED16: OK | EE16: 1.05 | EI16: 1.63 | FQ16: 9462110
B17: =C17&"x"&I17 -> 61013x100204 | C17: =IF(G17="SINGLE",H17,G17) -> 61013 | D17: =_xlfn.XLOOKUP(I17,calculations!$t:$t,calculations!$s:$s) -> #VALUE! | E17: =_xlfn.XLOOKUP(I17,Mapping!$T:$T,Mapping!$Q:$Q) -> DELT04 | F17: 46203 | G17: 61013 | H17: 61013 | I17: 100204 | J17: Delta Water B | K17: Investor 13 Mandate | L17: Investor 13 Mandate | M17: Infra Debt | N17: 298000 | O17: 348538.01 | P17: EUR | Q17: Private Placement Note | R17: N | S17: L100204 | T17: Infrastructure Debt | U17: GB | V17: United Kingdom | W17: Water | X17: CR1003 | Y17: 14.2 | Z17: GBP | AA17: 0.855 | AB17: Y | AC17: 572000 | AD17: 572000 | AE17: 669005.85 | AF17: 0.521 | AG17: 298000 | AH17: 298000 | AI17: 274000 | AJ17: 572000 | AK17: 298000 | AL17: 298000 | AN17: 4.364 | AO17: 4.443 | AP17: 2.762 | AQ17: 100 | AR17: 100 | AS17: 44791 | AT17: 54288 | AU17: 46295 | AV17: PI2003 | AW17: Corvus Digital | AX17: N | AY17: Delta Water Finance Ltd | AZ17: Delta Water Finance | BA17: United Kingdom | BB17: Corvus Digital | BC17: 529900SYNTH000000003 | BI17: 572000 | BJ17: 669005.85 | BK17: Fixed | BL17: Senior Secured | BN17: 15.6 | BO17: 22.14 | BP17: N | BQ17: N | BR17: Debt | BS17: RA100204 | BT17: A. Martin | BU17: C. Dubois | BW17: Semi-annual | BX17: 30/360 | BY17: 325 | BZ17: 325 | CC17: BBB+ | CD17: BBB+ | CE17: NR | CF17: NR | CG17: NR | CH17: 46112 | CI17: 1.2 | CJ17: 1.92 | CK17: 2.02 | CL17: OK | DA17: 0.83 | DC17: 0.85 | DD17: Watch | ED17: Watch | EE17: 1.05 | EI17: 1.13 | FQ17: 11051966
B18: =C18&"x"&I18 -> 61022x100203 | C18: =IF(G18="SINGLE",H18,G18) -> 61022 | D18: =_xlfn.XLOOKUP(I18,calculations!$t:$t,calculations!$s:$s) -> #VALUE! | E18: =_xlfn.XLOOKUP(I18,Mapping!$T:$T,Mapping!$Q:$Q) -> DELT04 | F18: 46203 | G18: 61022 | H18: 61022 | I18: 100203 | J18: Delta Water A | K18: Fund 2 Fund | L18: Fund 2 Fund | M18: Infra Debt | N18: 1213000 | O18: 1418713.4 | P18: EUR | Q18: Private Placement Note | R18: N | S18: L100203 | T18: Infrastructure Debt | U18: GB | V18: United Kingdom | W18: Water | X18: CR1003 | Y18: 14.2 | Z18: GBP | AA18: 0.855 | AB18: Y | AC18: 2331000 | AD18: 2331000 | AE18: 2726315.8 | AF18: 0.5204 | AG18: 1213000 | AH18: 1213000 | AI18: 1118000 | AJ18: 2331000 | AK18: 1213000 | AL18: 1213000 | AN18: 3.159 | AO18: 5.725 | AP18: 2.703 | AQ18: 100 | AR18: 100 | AS18: 44791 | AT18: 54288 | AU18: 46295 | AV18: PI2003 | AW18: Corvus Digital | AX18: N | AY18: Delta Water Finance Ltd | AZ18: Delta Water Finance | BA18: United Kingdom | BB18: Corvus Digital | BC18: 529900SYNTH000000003 | BI18: 2331000 | BJ18: 2726315.8 | BK18: Fixed | BL18: Senior Secured | BN18: 15.6 | BO18: 22.14 | BP18: N | BQ18: N | BR18: Debt | BS18: RA100203 | BT18: A. Martin | BU18: B. Okoro | BW18: Semi-annual | BX18: 30/360 | BY18: 325 | BZ18: 325 | CC18: BBB+ | CD18: BBB+ | CE18: NR | CF18: NR | CG18: NR | CH18: 46112 | CI18: 1.2 | CJ18: 2.54 | CK18: 2.67 | CL18: OK | DA18: 0.73 | DC18: 0.85 | DD18: OK | ED18: OK | EE18: 1.05 | EI18: 1.94 | FQ18: 12516714
B19: =C19&"x"&I19 -> 61022x100204 | C19: =IF(G19="SINGLE",H19,G19) -> 61022 | D19: =_xlfn.XLOOKUP(I19,calculations!$t:$t,calculations!$s:$s) -> #VALUE! | E19: =_xlfn.XLOOKUP(I19,Mapping!$T:$T,Mapping!$Q:$Q) -> DELT04 | F19: 46203 | G19: 61022 | H19: 61022 | I19: 100204 | J19: Delta Water B | K19: Fund 2 Fund | L19: Fund 2 Fund | M19: Infra Debt | N19: 809000 | O19: 946198.83 | P19: EUR | Q19: Private Placement Note | R19: N | S19: L100204 | T19: Infrastructure Debt | U19: GB | V19: United Kingdom | W19: Water | X19: CR1003 | Y19: 14.2 | Z19: GBP | AA19: 0.855 | AB19: Y | AC19: 1554000 | AD19: 1554000 | AE19: 1817543.9 | AF19: 0.5206 | AG19: 809000 | AH19: 809000 | AI19: 745000 | AJ19: 1554000 | AK19: 809000 | AL19: 809000 | AN19: 3.808 | AO19: 2.822 | AP19: 2.923 | AQ19: 100 | AR19: 100 | AS19: 44791 | AT19: 54288 | AU19: 46295 | AV19: PI2003 | AW19: Corvus Digital | AX19: N | AY19: Delta Water Finance Ltd | AZ19: Delta Water Finance | BA19: United Kingdom | BB19: Corvus Digital | BC19: 529900SYNTH000000003 | BI19: 1554000 | BJ19: 1817543.9 | BK19: Fixed | BL19: Senior Secured | BN19: 15.6 | BO19: 22.14 | BP19: N | BQ19: N | BR19: Debt | BS19: RA100204 | BT19: A. Martin | BU19: F. Lindqvist | BW19: Quarterly | BX19: ACT/360 | BY19: 325 | BZ19: 325 | CC19: BBB+ | CD19: BBB+ | CE19: NR | CF19: NR | CG19: NR | CH19: 46112 | CI19: 1.2 | CJ19: 3.47 | CK19: 3.64 | CL19: OK | DA19: 0.53 | DC19: 0.85 | DD19: OK | ED19: OK | EE19: 1.05 | EI19: 1.62 | FQ19: 11587832
B20: =C20&"x"&I20 -> 61017x100203 | C20: =IF(G20="SINGLE",H20,G20) -> 61017 | D20: =_xlfn.XLOOKUP(I20,calculations!$t:$t,calculations!$s:$s) -> #VALUE! | E20: =_xlfn.XLOOKUP(I20,Mapping!$T:$T,Mapping!$Q:$Q) -> DELT04 | F20: 46203 | G20: 61017 | H20: 61017 | I20: 100203 | J20: Delta Water A | K20: Investor 17 Mandate | L20: Investor 17 Mandate | M20: Infra Debt | N20: 706000 | O20: 825730.99 | P20: EUR | Q20: Private Placement Note | R20: N | S20: L100203 | T20: Infrastructure Debt | U20: GB | V20: United Kingdom | W20: Water | X20: CR1003 | Y20: 14.2 | Z20: GBP | AA20: 0.855 | AB20: Y | AC20: 1356000 | AD20: 1356000 | AE20: 1585964.9 | AF20: 0.5206 | AG20: 706000 | AH20: 706000 | AI20: 650000 | AJ20: 1356000 | AK20: 706000 | AL20: 706000 | AN20: 2.942 | AO20: 3.274 | AP20: 3.515 | AQ20: 100 | AR20: 100 | AS20: 44791 | AT20: 54288 | AU20: 46295 | AV20: PI2003 | AW20: Corvus Digital | AX20: N | AY20: Delta Water Finance Ltd | AZ20: Delta Water Finance | BA20: United Kingdom | BB20: Corvus Digital | BC20: 529900SYNTH000000003 | BI20: 1356000 | BJ20: 1585964.9 | BK20: Fixed | BL20: Senior Secured | BN20: 15.6 | BO20: 22.14 | BP20: N | BQ20: N | BR20: Debt | BS20: RA100203 | BT20: A. Martin | BU20: A. Martin | BW20: Quarterly | BX20: 30/360 | BY20: 325 | BZ20: 325 | CC20: BBB+ | CD20: BBB+ | CE20: NR | CF20: NR | CG20: NR | CH20: 46112 | CI20: 1.2 | CJ20: 2.75 | CK20: 2.89 | CL20: OK | DA20: 0.54 | DC20: 0.85 | DD20: OK | ED20: OK | EE20: 1.05 | EI20: 1.46 | FQ20: 9298998
B21: =C21&"x"&I21 -> 61017x100204 | C21: =IF(G21="SINGLE",H21,G21) -> 61017 | D21: =_xlfn.XLOOKUP(I21,calculations!$t:$t,calculations!$s:$s) -> #VALUE! | E21: =_xlfn.XLOOKUP(I21,Mapping!$T:$T,Mapping!$Q:$Q) -> DELT04 | F21: 46203 | G21: 61017 | H21: 61017 | I21: 100204 | J21: Delta Water B | K21: Investor 17 Mandate | L21: Investor 17 Mandate | M21: Infra Debt | N21: 471000 | O21: 550877.19 | P21: EUR | Q21: Private Placement Note | R21: N | S21: L100204 | T21: Infrastructure Debt | U21: GB | V21: United Kingdom | W21: Water | X21: CR1003 | Y21: 14.2 | Z21: GBP | AA21: 0.855 | AB21: Y | AC21: 904000 | AD21: 904000 | AE21: 1057309.9 | AF21: 0.521 | AG21: 471000 | AH21: 471000 | AI21: 433000 | AJ21: 904000 | AK21: 471000 | AL21: 471000 | AN21: 4.253 | AO21: 4.45 | AP21: 5.654 | AQ21: 100 | AR21: 100 | AS21: 44791 | AT21: 54288 | AU21: 46295 | AV21: PI2003 | AW21: Corvus Digital | AX21: N | AY21: Delta Water Finance Ltd | AZ21: Delta Water Finance | BA21: United Kingdom | BB21: Corvus Digital | BC21: 529900SYNTH000000003 | BI21: 904000 | BJ21: 1057309.9 | BK21: Fixed | BL21: Senior Secured | BN21: 15.6 | BO21: 22.14 | BP21: N | BQ21: N | BR21: Debt | BS21: RA100204 | BT21: A. Martin | BU21: B. Okoro | BW21: Semi-annual | BX21: 30/360 | BY21: 325 | BZ21: 325 | CC21: BBB+ | CD21: BBB+ | CE21: NR | CF21: NR | CG21: NR | CH21: 46112 | CI21: 1.2 | CJ21: 3.12 | CK21: 3.28 | CL21: OK | DA21: 0.72 | DC21: 0.85 | DD21: OK | ED21: Watch | EE21: 1.05 | EI21: 1.14 | FQ21: 8993354
B22: =C22&"x"&I22 -> 61019x100203 | C22: =IF(G22="SINGLE",H22,G22) -> 61019 | D22: =_xlfn.XLOOKUP(I22,calculations!$t:$t,calculations!$s:$s) -> #VALUE! | E22: =_xlfn.XLOOKUP(I22,Mapping!$T:$T,Mapping!$Q:$Q) -> DELT04 | F22: 46203 | G22: 61019 | H22: 61019 | I22: 100203 | J22: Delta Water A | K22: Investor 19 Mandate | L22: Investor 19 Mandate | M22: Infra Debt | N22: 1258000 | O22: 1471345 | P22: EUR | Q22: Private Placement Note | R22: N | S22: L100203 | T22: Infrastructure Debt | U22: GB | V22: United Kingdom | W22: Water | X22: CR1003 | Y22: 14.2 | Z22: GBP | AA22: 0.855 | AB22: Y | AC22: 2417000 | AD22: 2417000 | AE22: 2826900.6 | AF22: 0.5205 | AG22: 1258000 | AH22: 1258000 | AI22: 1159000 | AJ22: 2417000 | AK22: 1258000 | AL22: 1258000 | AN22: 3.116 | AO22: 4.798 | AP22: 5.089 | AQ22: 100 | AR22: 100 | AS22: 44791 | AT22: 54288 | AU22: 46295 | AV22: PI2003 | AW22: Corvus Digital | AX22: N | AY22: Delta Water Finance Ltd | AZ22: Delta Water Finance | BA22: United Kingdom | BB22: Corvus Digital | BC22: 529900SYNTH000000003 | BI22: 2417000 | BJ22: 2826900.6 | BK22: Fixed | BL22: Senior Secured | BN22: 15.6 | BO22: 22.14 | BP22: N | BQ22: N | BR22: Debt | BS22: RA100203 | BT22: A. Martin | BU22: F. Lindqvist | BW22: Semi-annual | BX22: 30/360 | BY22: 325 | BZ22: 325 | CC22: BBB+ | CD22: BBB+ | CE22: NR | CF22: NR | CG22: NR | CH22: 46112 | CI22: 1.2 | CJ22: 2.11 | CK22: 2.22 | CL22: OK | DA22: 0.71 | DC22: 0.85 | DD22: OK | ED22: OK | EE22: 1.05 | EI22: 1.73 | FQ22: 9598306
B23: =C23&"x"&I23 -> 61019x100204 | C23: =IF(G23="SINGLE",H23,G23) -> 61019 | D23: =_xlfn.XLOOKUP(I23,calculations!$t:$t,calculations!$s:$s) -> #VALUE! | E23: =_xlfn.XLOOKUP(I23,Mapping!$T:$T,Mapping!$Q:$Q) -> DELT04 | F23: 46203 | G23: 61019 | H23: 61019 | I23: 100204 | J23: Delta Water B | K23: Investor 19 Mandate | L23: Investor 19 Mandate | M23: Infra Debt | N23: 839000 | O23: 981286.55 | P23: EUR | Q23: Private Placement Note | R23: N | S23: L100204 | T23: Infrastructure Debt | U23: GB | V23: United Kingdom | W23: Water | X23: CR1003 | Y23: 14.2 | Z23: GBP | AA23: 0.855 | AB23: Y | AC23: 1612000 | AD23: 1612000 | AE23: 1885380.1 | AF23: 0.5205 | AG23: 839000 | AH23: 839000 | AI23: 773000 | AJ23: 1612000 | AK23: 839000 | AL23: 839000 | AN23: 5.316 | AO23: 6.075 | AP23: 4.964 | AQ23: 100 | AR23: 100 | AS23: 44791 | AT23: 54288 | AU23: 46295 | AV23: PI2003 | AW23: Corvus Digital | AX23: N | AY23: Delta Water Finance Ltd | AZ23: Delta Water Finance | BA23: United Kingdom | BB23: Corvus Digital | BC23: 529900SYNTH000000003 | BI23: 1612000 | BJ23: 1885380.1 | BK23: Fixed | BL23: Senior Secured | BN23: 15.6 | BO23: 22.14 | BP23: N | BQ23: N | BR23: Debt | BS23: RA100204 | BT23: A. Martin | BU23: C. Dubois | BW23: Quarterly | BX23: ACT/360 | BY23: 325 | BZ23: 325 | CC23: BBB+ | CD23: BBB+ | CE23: NR | CF23: NR | CG23: NR | CH23: 46112 | CI23: 1.2 | CJ23: 1.23 | CK23: 1.29 | CL23: Watch | DA23: 0.78 | DC23: 0.85 | DD23: OK | ED23: OK | EE23: 1.05 | EI23: 1.73 | FQ23: 8770079
... B39: =C39&"x"&I39 -> 61005x100206 | C39: =IF(G39="SINGLE",H39,G39) -> 61005 | D39: =_xlfn.XLOOKUP(I39,calculations!$t:$t,calculations!$s:$s) -> #VALUE! | E39: =_xlfn.XLOOKUP(I39,Mapping!$T:$T,Mapping!$Q:$Q) -> EMBE05 | F39: 46203 | G39: 61005 | H39: 61005 | I39: 100206 | J39: Ember Battery B | K39: Investor 5 Portfolio | L39: Investor 5 Portfolio | M39: Infra Debt | N39: 5267000 | O39: 5267000 | P39: EUR | Q39: Loan | R39: N | S39: L100206 | T39: Infrastructure Debt | U39: IT | V39: Italy | W39: Battery storage | X39: CR1004 | Y39: 8.1 | Z39: EUR | AA39: 1 | AB39: N | AC39: 5683000 | AD39: 5683000 | AE39: 5683000 | AF39: 0.9268 | AG39: 5267000 | AH39: 5267000 | AI39: 416000 | AJ39: 5683000 | AK39: 5267000 | AL39: 5267000 | AN39: 4.278 | AO39: 3.432 | AP39: 5.278 | AQ39: 100 | AR39: 100 | AS39: 44791 | AT39: 48809 | AU39: 46295 | AV39: PI2004 | AW39: Terra Social Infra | AX39: N | AY39: Ember Battery Finance Ltd | AZ39: Ember Battery Finance | BA39: Italy | BB39: Terra Social Infra | BC39: 529900SYNTH000000004 | BI39: 5683000 | BJ39: 5683000 | BK39: Fixed | BL39: Senior Secured | BN39: 6.6 | BO39: 7.13 | BP39: N | BQ39: N | BR39: Debt | BS39: RA100206 | BT39: D. Schäfer | BU39: E. Rossi | BW39: Semi-annual | BX39: 30/360 | BY39: 245 | BZ39: 245 | CC39: BB- | CD39: BB- | CE39: BB- | CF39: NR | CG39: NR | CH39: 46112 | CI39: 1.2 | CJ39: 2.12 | CK39: 2.23 | CL39: OK | DA39: 0.59 | DC39: 0.85 | DD39: OK | ED39: OK | EE39: 1.05 | EI39: 1.51 | FQ39: 45818448
B40: =C40&"x"&I40 -> 61003x100207 | C40: =IF(G40="SINGLE",H40,G40) -> 61003 | D40: =_xlfn.XLOOKUP(I40,calculations!$t:$t,calculations!$s:$s) -> #VALUE! | E40: =_xlfn.XLOOKUP(I40,Mapping!$T:$T,Mapping!$Q:$Q) -> FALC06 | F40: 46203 | G40: 61003 | H40: 61003 | I40: 100207 | J40: Falcon Hospitals | K40: Investor 3 Portfolio | L40: Investor 3 Portfolio | M40: Infra Debt | N40: 23405000 | O40: 27374269 | P40: EUR | Q40: Private Placement Note | R40: Y | S40: L100207 | T40: Infrastructure Debt | U40: GB | V40: United Kingdom | W40: Hospitals (PPP) | X40: CR1005 | Y40: 10.6 | Z40: GBP | AA40: 0.855 | AB40: Y | AC40: 24564000 | AD40: 24564000 | AE40: 28729825 | AF40: 0.9528 | AG40: 23405000 | AH40: 23405000 | AI40: 1159000 | AJ40: 24564000 | AK40: 23405000 | AL40: 23405000 | AM40: EURIBOR 6M | AN40: 2.564 | AO40: 6.433 | AP40: 6.369 | AQ40: 100 | AR40: 100 | AS40: 45246 | AT40: 51456 | AU40: 46295 | AV40: PI2005 | AW40: Northwind Capital | AX40: N | AY40: Falcon Hospitals Finance Ltd | AZ40: Falcon Hospitals Finance | BA40: United Kingdom | BB40: Northwind Capital | BC40: 529900SYNTH000000005 | BI40: 24564000 | BJ40: 28729825 | BK40: Floating | BL40: Senior Secured | BN40: 10.2 | BO40: 14.38 | BP40: Y | BQ40: Y | BR40: Debt | BS40: RA100207 | BT40: B. Okoro | BU40: A. Martin | BW40: Semi-annual | BX40: ACT/360 | BY40: 255 | BZ40: 255 | CB40: EURIBOR | CC40: BBB | CD40: BBB | CE40: BBB+ | CF40: NR | CG40: Baa3 | CH40: 46112 | CI40: 1.2 | CJ40: 2.4 | CK40: 2.52 | CL40: OK | DA40: 0.45 | DC40: 0.85 | DD40: OK | ED40: OK | EE40: 1.05 | EI40: 1.94 | FQ40: 11531835
B41: =C41&"x"&I41 -> 61015x100207 | C41: =IF(G41="SINGLE",H41,G41) -> 61015 | D41: =_xlfn.XLOOKUP(I41,calculations!$t:$t,calculations!$s:$s) -> #VALUE! | E41: =_xlfn.XLOOKUP(I41,Mapping!$T:$T,Mapping!$Q:$Q) -> FALC06 | F41: 46203 | G41: 61015 | H41: 61015 | I41: 100207 | J41: Falcon Hospitals | K41: Investor 15 Mandate | L41: Investor 15 Mandate | M41: Infra Debt | N41: 15106000 | O41: 17667836 | P41: EUR | Q41: Private Placement Note | R41: Y | S41: L100207 | T41: Infrastructure Debt | U41: GB | V41: United Kingdom | W41: Hospitals (PPP) | X41: CR1005 | Y41: 10.6 | Z41: GBP | AA41: 0.855 | AB41: Y | AC41: 15854000 | AD41: 15854000 | AE41: 18542690 | AF41: 0.9528 | AG41: 15106000 | AH41: 15106000 | AI41: 748000 | AJ41: 15854000 | AK41: 15106000 | AL41: 15106000 | AM41: EURIBOR 6M | AN41: 6.262 | AO41: 2.776 | AP41: 5.614 | AQ41: 100 | AR41: 100 | AS41: 45246 | AT41: 51456 | AU41: 46295 | AV41: PI2005 | AW41: Northwind Capital | AX41: N | AY41: Falcon Hospitals Finance Ltd | AZ41: Falcon Hospitals Finance | BA41: United Kingdom | BB41: Northwind Capital | BC41: 529900SYNTH000000005 | BI41: 15854000 | BJ41: 18542690 | BK41: Floating | BL41: Senior Secured | BN41: 10.2 | BO41: 14.38 | BP41: Y | BQ41: Y | BR41: Debt | BS41: RA100207 | BT41: B. Okoro | BU41: D. Schäfer | BW41: Semi-annual | BX41: ACT/360 | BY41: 255 | BZ41: 255 | CB41: EURIBOR | CC41: BBB | CD41: BBB | CE41: BBB+ | CF41: NR | CG41: Baa3 | CH41: 46112 | CI41: 1.2 | CJ41: 2.5 | CK41: 2.63 | CL41: OK | DA41: 0.54 | DC41: 0.85 | DD41: OK | ED41: OK | EE41: 1.05 | EI41: 1.29 | FQ41: 17538903
B42: =C42&"x"&I42 -> 61019x100207 | C42: =IF(G42="SINGLE",H42,G42) -> 61019 | D42: =_xlfn.XLOOKUP(I42,calculations!$t:$t,calculations!$s:$s) -> #VALUE! | E42: =_xlfn.XLOOKUP(I42,Mapping!$T:$T,Mapping!$Q:$Q) -> FALC06 | F42: 46203 | G42: 61019 | H42: 61019 | I42: 100207 | J42: Falcon Hospitals | K42: Investor 19 Mandate | L42: Investor 19 Mandate | M42: Infra Debt | N42: 13357000 | O42: 15622222 | P42: EUR | Q42: Private Placement Note | R42: Y | S42: L100207 | T42: Infrastructure Debt | U42: GB | V42: United Kingdom | W42: Hospitals (PPP) | X42: CR1005 | Y42: 10.6 | Z42: GBP | AA42: 0.855 | AB42: Y | AC42: 14019000 | AD42: 14019000 | AE42: 16396491 | AF42: 0.9528 | AG42: 13357000 | AH42: 13357000 | AI42: 662000 | AJ42: 14019000 | AK42: 13357000 | AL42: 13357000 | AM42: EURIBOR 6M | AN42: 6.147 | AO42: 3.883 | AP42: 3.477 | AQ42: 100 | AR42: 100 | AS42: 45246 | AT42: 51456 | AU42: 46295 | AV42: PI2005 | AW42: Northwind Capital | AX42: N | AY42: Falcon Hospitals Finance Ltd | AZ42: Falcon Hospitals Finance | BA42: United Kingdom | BB42: Northwind Capital | BC42: 529900SYNTH000000005 | BI42: 14019000 | BJ42: 16396491 | BK42: Floating | BL42: Senior Secured | BN42: 10.2 | BO42: 14.38 | BP42: Y | BQ42: Y | BR42: Debt | BS42: RA100207 | BT42: B. Okoro | BU42: A. Martin | BW42: Semi-annual | BX42: 30/360 | BY42: 255 | BZ42: 255 | CB42: EURIBOR | CC42: BBB | CD42: BBB | CE42: BBB+ | CF42: NR | CG42: Baa3 | CH42: 46112 | CI42: 1.2 | CJ42: 2.66 | CK42: 2.79 | CL42: OK | DA42: 0.84 | DC42: 0.85 | DD42: Watch | ED42: OK | EE42: 1.05 | EI42: 1.63 | FQ42: 15740291
B43: =C43&"x"&I43 -> 61022x100207 | C43: =IF(G43="SINGLE",H43,G43) -> 61022 | D43: =_xlfn.XLOOKUP(I43,calculations!$t:$t,calculations!$s:$s) -> #VALUE! | E43: =_xlfn.XLOOKUP(I43,Mapping!$T:$T,Mapping!$Q:$Q) -> FALC06 | F43: 46203 | G43: 61022 | H43: 61022 | I43: 100207 | J43: Falcon Hospitals | K43: Fund 2 Fund | L43: Fund 2 Fund | M43: Infra Debt | N43: 21398000 | O43: 25026901 | P43: EUR | Q43: Private Placement Note | R43: Y | S43: L100207 | T43: Infrastructure Debt | U43: GB | V43: United Kingdom | W43: Hospitals (PPP) | X43: CR1005 | Y43: 10.6 | Z43: GBP | AA43: 0.855 | AB43: Y | AC43: 22458000 | AD43: 22458000 | AE43: 26266667 | AF43: 0.9528 | AG43: 21398000 | AH43: 21398000 | AI43: 1060000 | AJ43: 22458000 | AK43: 21398000 | AL43: 21398000 | AM43: EURIBOR 6M | AN43: 3.491 | AO43: 2.595 | AP43: 3.331 | AQ43: 100 | AR43: 100 | AS43: 45246 | AT43: 51456 | AU43: 46295 | AV43: PI2005 | AW43: Northwind Capital | AX43: N | AY43: Falcon Hospitals Finance Ltd | AZ43: Falcon Hospitals Finance | BA43: United Kingdom | BB43: Northwind Capital | BC43: 529900SYNTH000000005 | BI43: 22458000 | BJ43: 26266667 | BK43: Floating | BL43: Senior Secured | BN43: 10.2 | BO43: 14.38 | BP43: Y | BQ43: Y | BR43: Debt | BS43: RA100207 | BT43: B. Okoro | BU43: D. Schäfer | BW43: Quarterly | BX43: 30/360 | BY43: 255 | BZ43: 255 | CB43: EURIBOR | CC43: BBB | CD43: BBB | CE43: BBB+ | CF43: NR | CG43: Baa3 | CH43: 46112 | CI43: 1.2 | CJ43: 3.09 | CK43: 3.24 | CL43: OK | DA43: 0.64 | DC43: 0.85 | DD43: OK | ED43: OK | EE43: 1.05 | EI43: 1.75 | FQ43: 18858372
B44: =C44&"x"&I44 -> 61023x100208 | C44: =IF(G44="SINGLE",H44,G44) -> 61023 | D44: =_xlfn.XLOOKUP(I44,calculations!$t:$t,calculations!$s:$s) -> #VALUE! | E44: =_xlfn.XLOOKUP(I44,Mapping!$T:$T,Mapping!$Q:$Q) -> GRAN07 | F44: 46203 | G44: 61023 | H44: 61023 | I44: 100208 | J44: Granite Hydro | K44: Fund 3 Fund | L44: Fund 3 Fund | M44: Infra Debt | N44: 41561000 | O44: 41561000 | P44: EUR | Q44: Loan | R44: N | S44: L100208 | T44: Infrastructure Debt | U44: IE | V44: Ireland | W44: Hydro | X44: CR1006 | Y44: 8.7 | Z44: EUR | AA44: 1 | AB44: N | AC44: 41061000 | AD44: 41061000 | AE44: 41061000 | AF44: 1.0122 | AG44: 41561000 | AH44: 41561000 | AI44: -500000 | AJ44: 41061000 | AK44: 41561000 | AL44: 41561000 | AM44: EURIBOR 6M | AN44: 5.629 | AO44: 3.943 | AP44: 2.581 | AQ44: 100 | AR44: 100 | AS44: 42133 | AT44: 47431 | AU44: 46295 | AV44: PI2006 | AW44: Meridian Infrastructure | AX44: N | AY44: Granite Hydro Finance Ltd | AZ44: Granite Hydro Finance | BA44: Ireland | BB44: Meridian Infrastructure | BC44: 529900SYNTH000000006 | BI44: 41061000 | BJ44: 41061000 | BK44: Floating | BL44: Senior Secured | BN44: 8.7 | BO44: 3.36 | BP44: Y | BQ44: N | BR44: Debt | BS44: RA100208 | BT44: D. Schäfer | BU44: F. Lindqvist | BW44: Semi-annual | BX44: ACT/360 | BY44: 220 | BZ44: 220 | CB44: EURIBOR | CC44: AA- | CD44: AA- | CE44: AA- | CF44: AA | CG44: NR | CH44: 46112 | CI44: 1.2 | CJ44: 1.7 | CK44: 1.78 | CL44: OK | DA44: 0.55 | DC44: 0.85 | DD44: OK | ED44: OK | EE44: 1.05 | EI44: 1.7 | FQ44: 82486249
B45: =C45&"x"&I45 -> 61021x100208 | C45: =IF(G45="SINGLE",H45,G45) -> 61021 | D45: =_xlfn.XLOOKUP(I45,calculations!$t:$t,calculations!$s:$s) -> #VALUE! | E45: =_xlfn.XLOOKUP(I45,Mapping!$T:$T,Mapping!$Q:$Q) -> GRAN07 | F45: 46203 | G45: 61021 | H45: 61021 | I45: 100208 | J45: Granite Hydro | K45: Fund 1 Fund | L45: Fund 1 Fund | M45: Infra Debt | N45: 35221000 | O45: 35221000 | P45: EUR | Q45: Loan | R45: N | S45: L100208 | T45: Infrastructure Debt | U45: IE | V45: Ireland | W45: Hydro | X45: CR1006 | Y45: 8.7 | Z45: EUR | AA45: 1 | AB45: N | AC45: 35577000 | AD45: 35577000 | AE45: 35577000 | AF45: 0.99 | AG45: 35221000 | AH45: 35221000 | AI45: 356000 | AJ45: 35577000 | AK45: 35221000 | AL45: 35221000 | AM45: EURIBOR 6M | AN45: 3.58 | AO45: 3.56 | AP45: 6.015 | AQ45: 100 | AR45: 100 | AS45: 42133 | AT45: 47431 | AU45: 46295 | AV45: PI2006 | AW45: Meridian Infrastructure | AX45: N | AY45: Granite Hydro Finance Ltd | AZ45: Granite Hydro Finance | BA45: Ireland | BB45: Meridian Infrastructure | BC45: 529900SYNTH000000006 | BI45: 35577000 | BJ45: 35577000 | BK45: Floating | BL45: Senior Secured | BN45: 8.7 | BO45: 3.36 | BP45: Y | BQ45: N | BR45: Debt | BS45: RA100208 | BT45: D. Schäfer | BU45: E. Rossi | BW45: Quarterly | BX45: ACT/360 | BY45: 220 | BZ45: 220 | CB45: EURIBOR | CC45: AA- | CD45: AA- | CE45: AA- | CF45: AA | CG45: NR | CH45: 46112 | CI45: 1.2 | CJ45: 1.33 | CK45: 1.4 | CL45: OK | DA45: 0.79 | DC45: 0.85 | DD45: OK | ED45: Watch | EE45: 1.05 | EI45: 1.18 | FQ45: 62491674
B46: =C46&"x"&I46 -> 61007x100208 | C46: =IF(G46="SINGLE",H46,G46) -> 61007 | D46: =_xlfn.XLOOKUP(I46,calculations!$t:$t,calculations!$s:$s) -> #VALUE! | E46: =_xlfn.XLOOKUP(I46,Mapping!$T:$T,Mapping!$Q:$Q) -> GRAN07 | F46: 46203 | G46: 61007 | H46: 61007 | I46: 100208 | J46: Granite Hydro | K46: Investor 7 Portfolio | L46: Investor 7 Portfolio | M46: Infra Debt | N46: 61220000 | O46: 61220000 | P46: GBP | Q46: Loan | R46: N | S46: L100208 | T46: Infrastructure Debt | U46: IE | V46: Ireland | W46: Hydro | X46: CR1006 | Y46: 8.7 | Z46: EUR | AA46: 1 | AB46: N | AC46: 61840000 | AD46: 61840000 | AE46: 61840000 | AF46: 0.99 | AG46: 61220000 | AH46: 61220000 | AI46: 620000 | AJ46: 61840000 | AK46: 61220000 | AL46: 61220000 | AM46: EURIBOR 6M | AN46: 4.593 | AO46: 6.081 | AP46: 3.184 | AQ46: 100 | AR46: 100 | AS46: 42133 | AT46: 47431 | AU46: 46295 | AV46: PI2006 | AW46: Meridian Infrastructure | AX46: N | AY46: Granite Hydro Finance Ltd | AZ46: Granite Hydro Finance | BA46: Ireland | BB46: Meridian Infrastructure | BC46: 529900SYNTH000000006 | BI46: 61840000 | BJ46: 61840000 | BK46: Floating | BL46: Senior Secured | BN46: 8.7 | BO46: 3.36 | BP46: Y | BQ46: N | BR46: Debt | BS46: RA100208 | BT46: D. Schäfer | BU46: D. Schäfer | BW46: Quarterly | BX46: 30/360 | BY46: 220 | BZ46: 220 | CB46: EURIBOR | CC46: AA- | CD46: AA- | CE46: AA- | CF46: AA | CG46: NR | CH46: 46112 | CI46: 1.2 | CJ46: 1.4 | CK46: 1.47 | CL46: OK | DA46: 0.48 | DC46: 0.85 | DD46: OK | ED46: OK | EE46: 1.05 | EI46: 1.82 | FQ46: 90643678
B47: =C47&"x"&I47 -> 61005x100208 | C47: =IF(G47="SINGLE",H47,G47) -> 61005 | D47: =_xlfn.XLOOKUP(I47,calculations!$t:$t,calculations!$s:$s) -> #VALUE! | E47: =_xlfn.XLOOKUP(I47,Mapping!$T:$T,Mapping!$Q:$Q) -> GRAN07 | F47: 46203 | G47: 61005 | H47: 61005 | I47: 100208 | J47: Granite Hydro | K47: Investor 5 Portfolio | L47: Investor 5 Portfolio | M47: Infra Debt | N47: 45422000 | O47: 45422000 | P47: EUR | Q47: Loan | R47: N | S47: L100208 | T47: Infrastructure Debt | U47: IE | V47: Ireland | W47: Hydro | X47: CR1006 | Y47: 8.7 | Z47: EUR | AA47: 1 | AB47: N | AC47: 45882000 | AD47: 45882000 | AE47: 45882000 | AF47: 0.99 | AG47: 45422000 | AH47: 45422000 | AI47: 460000 | AJ47: 45882000 | AK47: 45422000 | AL47: 45422000 | AM47: EURIBOR 6M | AN47: 2.573 | AO47: 5.074 | AP47: 6.47 | AQ47: 100 | AR47: 100 | AS47: 42133 | AT47: 47431 | AU47: 46295 | AV47: PI2006 | AW47: Meridian Infrastructure | AX47: N | AY47: Granite Hydro Finance Ltd | AZ47: Granite Hydro Finance | BA47: Ireland | BB47: Meridian Infrastructure | BC47: 529900SYNTH000000006 | BI47: 45882000 | BJ47: 45882000 | BK47: Floating | BL47: Senior Secured | BN47: 8.7 | BO47: 3.36 | BP47: Y | BQ47: N | BR47: Debt | BS47: RA100208 | BT47: D. Schäfer | BU47: F. Lindqvist | BW47: Quarterly | BX47: ACT/360 | BY47: 220 | BZ47: 220 | CB47: EURIBOR | CC47: AA- | CD47: AA- | CE47: AA- | CF47: AA | CG47: NR | CH47: 46112 | CI47: 1.2 | CJ47: 2.26 | CK47: 2.37 | CL47: OK | DA47: 0.8 | DC47: 0.85 | DD47: Watch | ED47: Watch | EE47: 1.05 | EI47: 1.15 | FQ47: 72978372
B48: =C48&"x"&I48 -> 61025x100208 | C48: =IF(G48="SINGLE",H48,G48) -> 61025 | D48: =_xlfn.XLOOKUP(I48,calculations!$t:$t,calculations!$s:$s) -> #VALUE! | E48: =_xlfn.XLOOKUP(I48,Mapping!$T:$T,Mapping!$Q:$Q) -> GRAN07 | F48: 46203 | G48: 61025 | H48: 61025 | I48: 100208 | J48: Granite Hydro | K48: Fund 5 Fund | L48: Fund 5 Fund | M48: Infra Debt | N48: 27925000 | O48: 27925000 | P48: EUR | Q48: Loan | R48: N | S48: L100208 | T48: Infrastructure Debt | U48: IE | V48: Ireland | W48: Hydro | X48: CR1006 | Y48: 8.7 | Z48: EUR | AA48: 1 | AB48: N | AC48: 28208000 | AD48: 28208000 | AE48: 28208000 | AF48: 0.99 | AG48: 27925000 | AH48: 27925000 | AI48: 283000 | AJ48: 28208000 | AK48: 27925000 | AL48: 27925000 | AM48: EURIBOR 6M | AN48: 2.724 | AO48: 4.659 | AP48: 4.826 | AQ48: 100 | AR48: 100 | AS48: 42133 | AT48: 47431 | AU48: 46295 | AV48: PI2006 | AW48: Meridian Infrastructure | AX48: N | AY48: Granite Hydro Finance Ltd | AZ48: Granite Hydro Finance | BA48: Ireland | BB48: Meridian Infrastructure | BC48: 529900SYNTH000000006 | BI48: 28208000 | BJ48: 28208000 | BK48: Floating | BL48: Senior Secured | BN48: 8.7 | BO48: 3.36 | BP48: Y | BQ48: N | BR48: Debt | BS48: RA100208 | BT48: D. Schäfer | BU48: A. Martin | BW48: Semi-annual | BX48: ACT/360 | BY48: 220 | BZ48: 220 | CB48: EURIBOR | CC48: AA- | CD48: AA- | CE48: AA- | CF48: AA | CG48: NR | CH48: 46112 | CI48: 1.2 | CJ48: 2.53 | CK48: 2.66 | CL48: OK | DA48: 0.74 | DC48: 0.85 | DD48: OK | ED48: OK | EE48: 1.05 | EI48: 1.42 | FQ48: 71712307
B49: =C49&"x"&I49 -> 61022x100208 | C49: =IF(G49="SINGLE",H49,G49) -> 61022 | D49: =_xlfn.XLOOKUP(I49,calculations!$t:$t,calculations!$s:$s) -> #VALUE! | E49: =_xlfn.XLOOKUP(I49,Mapping!$T:$T,Mapping!$Q:$Q) -> GRAN07 | F49: 46203 | G49: 61022 | H49: 61022 | I49: 100208 | J49: Granite Hydro | K49: Fund 2 Fund | L49: Fund 2 Fund | M49: Infra Debt | N49: 33303000 | O49: 33303000 | P49: EUR | Q49: Loan | R49: N | S49: L100208 | T49: Infrastructure Debt | U49: IE | V49: Ireland | W49: Hydro | X49: CR1006 | Y49: 8.7 | Z49: EUR | AA49: 1 | AB49: N | AC49: 33640000 | AD49: 33640000 | AE49: 33640000 | AF49: 0.99 | AG49: 33303000 | AH49: 33303000 | AI49: 337000 | AJ49: 33640000 | AK49: 33303000 | AL49: 33303000 | AM49: EURIBOR 6M | AN49: 5.516 | AO49: 4.693 | AP49: 5.93 | AQ49: 100 | AR49: 100 | AS49: 42133 | AT49: 47431 | AU49: 46295 | AV49: PI2006 | AW49: Meridian Infrastructure | AX49: N | AY49: Granite Hydro Finance Ltd | AZ49: Granite Hydro Finance | BA49: Ireland | BB49: Meridian Infrastructure | BC49: 529900SYNTH000000006 | BI49: 33640000 | BJ49: 33640000 | BK49: Floating | BL49: Senior Secured | BN49: 8.7 | BO49: 3.36 | BP49: Y | BQ49: N | BR49: Debt | BS49: RA100208 | BT49: D. Schäfer | BU49: A. Martin | BW49: Quarterly | BX49: ACT/360 | BY49: 220 | BZ49: 220 | CB49: EURIBOR | CC49: AA- | CD49: AA- | CE49: AA- | CF49: AA | CG49: NR | CH49: 46112 | CI49: 1.2 | CJ49: 2.81 | CK49: 2.95 | CL49: OK | DA49: 0.47 | DC49: 0.85 | DD49: OK | ED49: OK | EE49: 1.05 | EI49: 1.42 | FQ49: 88445686
B50: =C50&"x"&I50 -> 61020x100209 | C50: =IF(G50="SINGLE",H50,G50) -> 61020 | D50: =_xlfn.XLOOKUP(I50,calculations!$t:$t,calculations!$s:$s) -> #VALUE! | E50: =_xlfn.XLOOKUP(I50,Mapping!$T:$T,Mapping!$Q:$Q) -> HARB08 | F50: 46203 | G50: 61020 | H50: 61020 | I50: 100209 | J50: Harbour Toll | K50: Investor 20 Mandate | L50: Investor 20 Mandate | M50: Infra Debt | N50: 28566000 | O50: 28566000 | P50: EUR | Q50: Loan | R50: Y | S50: L100209 | T50: Infrastructure Debt | U50: NL | V50: Netherlands | W50: Toll roads | X50: CR1007 | Y50: 11.5 | Z50: EUR | AA50: 1 | AB50: N | AC50: 29108000 | AD50: 29108000 | AE50: 29108000 | AF50: 0.9814 | AG50: 28566000 | AH50: 28566000 | AI50: 542000 | AJ50: 29108000 | AK50: 28566000 | AL50: 28566000 | AN50: 5.726 | AO50: 3.988 | AP50: 6.237 | AQ50: 100 | AR50: 100 | AS50: 45739 | AT50: 51948 | AU50: 46295 | AV50: PI2007 | AW50: Helios Partners | AX50: N | AY50: Harbour Toll Finance Ltd | AZ50: Harbour Toll Finance | BA50: Netherlands | BB50: Helios Partners | BC50: 529900SYNTH000000007 | BI50: 29108000 | BJ50: 29108000 | BK50: Fixed | BL50: Senior Secured | BN50: 10.2 | BO50: 15.73 | BP50: N | BQ50: Y | BR50: Debt | BS50: RA100209 | BT50: D. Schäfer | BU50: B. Okoro | BW50: Semi-annual | BX50: 30/360 | BY50: 305 | BZ50: 305 | CC50: BBB | CD50: BBB | CE50: NR | CF50: NR | CG50: NR | CH50: 46112 | CI50: 1.2 | CJ50: 1.62 | CK50: 1.7 | CL50: OK | DA50: 0.58 | DC50: 0.85 | DD50: OK | ED50: OK | EE50: 1.05 | EI50: 1.46 | FQ50: 36665988
B51: =C51&"x"&I51 -> 61017x100209 | C51: =IF(G51="SINGLE",H51,G51) -> 61017 | D51: =_xlfn.XLOOKUP(I51,calculations!$t:$t,calculations!$s:$s) -> #VALUE! | E51: =_xlfn.XLOOKUP(I51,Mapping!$T:$T,Mapping!$Q:$Q) -> HARB08 | F51: 46203 | G51: 61017 | H51: 61017 | I51: 100209 | J51: Harbour Toll | K51: Investor 17 Mandate | L51: Investor 17 Mandate | M51: Infra Debt | N51: 30236000 | O51: 30236000 | P51: EUR | Q51: Loan | R51: Y | S51: L100209 | T51: Infrastructure Debt | U51: NL | V51: Netherlands | W51: Toll roads | X51: CR1007 | Y51: 11.5 | Z51: EUR | AA51: 1 | AB51: N | AC51: 30810000 | AD51: 30810000 | AE51: 30810000 | AF51: 0.9814 | AG51: 30236000 | AH51: 30236000 | AI51: 574000 | AJ51: 30810000 | AK51: 30236000 | AL51: 30236000 | AN51: 3.119 | AO51: 4.088 | AP51: 5.873 | AQ51: 100 | AR51: 100 | AS51: 45739 | AT51: 51948 | AU51: 46295 | AV51: PI2007 | AW51: Helios Partners | AX51: N | AY51: Harbour Toll Finance Ltd | AZ51: Harbour Toll Finance | BA51: Netherlands | BB51: Helios Partners | BC51: 529900SYNTH000000007 | BI51: 30810000 | BJ51: 30810000 | BK51: Fixed | BL51: Senior Secured | BN51: 10.2 | BO51: 15.73 | BP51: N | BQ51: Y | BR51: Debt | BS51: RA100209 | BT51: D. Schäfer | BU51: B. Okoro | BW51: Quarterly | BX51: ACT/360 | BY51: 305 | BZ51: 305 | CC51: BBB | CD51: BBB | CE51: NR | CF51: NR | CG51: NR | CH51: 46112 | CI51: 1.2 | CJ51: 2.94 | CK51: 3.09 | CL51: OK | DA51: 0.72 | DC51: 0.85 | DD51: OK | ED51: OK | EE51: 1.05 | EI51: 1.38 | FQ51: 37799275
B52: =C52&"x"&I52 -> 61015x100209 | C52: =IF(G52="SINGLE",H52,G52) -> 61015 | D52: =_xlfn.XLOOKUP(I52,calculations!$t:$t,calculations!$s:$s) -> #VALUE! | E52: =_xlfn.XLOOKUP(I52,Mapping!$T:$T,Mapping!$Q:$Q) -> HARB08 | F52: 46203 | G52: 61015 | H52: 61015 | I52: 100209 | J52: Harbour Toll | K52: Investor 15 Mandate | L52: Investor 15 Mandate | M52: Infra Debt | N52: 17602000 | O52: 17602000 | P52: EUR | Q52: Loan | R52: Y | S52: L100209 | T52: Infrastructure Debt | U52: NL | V52: Netherlands | W52: Toll roads | X52: CR1007 | Y52: 11.5 | Z52: EUR | AA52: 1 | AB52: N | AC52: 17936000 | AD52: 17936000 | AE52: 17936000 | AF52: 0.9814 | AG52: 17602000 | AH52: 17602000 | AI52: 334000 | AJ52: 17936000 | AK52: 17602000 | AL52: 17602000 | AN52: 4.338 | AO52: 5.936 | AP52: 5.371 | AQ52: 100 | AR52: 100 | AS52: 45739 | AT52: 51948 | AU52: 46295 | AV52: PI2007 | AW52: Helios Partners | AX52: N | AY52: Harbour Toll Finance Ltd | AZ52: Harbour Toll Finance | BA52: Netherlands | BB52: Helios Partners | BC52: 529900SYNTH000000007 | BI52: 17936000 | BJ52: 17936000 | BK52: Fixed | BL52: Senior Secured | BN52: 10.2 | BO52: 15.73 | BP52: N | BQ52: Y | BR52: Debt | BS52: RA100209 | BT52: D. Schäfer | BU52: B. Okoro | BW52: Quarterly | BX52: ACT/360 | BY52: 305 | BZ52: 305 | CC52: BBB | CD52: BBB | CE52: NR | CF52: NR | CG52: NR | CH52: 46112 | CI52: 1.2 | CJ52: 3.25 | CK52: 3.41 | CL52: OK | DA52: 0.67 | DC52: 0.85 | DD52: OK | ED52: OK | EE52: 1.05 | EI52: 1.89 | FQ52: 36275326
B53: =C53&"x"&I53 -> 61012x100209 | C53: =IF(G53="SINGLE",H53,G53) -> 61012 | D53: =_xlfn.XLOOKUP(I53,calculations!$t:$t,calculations!$s:$s) -> #VALUE! | E53: =_xlfn.XLOOKUP(I53,Mapping!$T:$T,Mapping!$Q:$Q) -> HARB08 | F53: 46203 | G53: 61012 | H53: 61012 | I53: 100209 | J53: Harbour Toll | K53: Investor 12 Mandate | L53: Investor 12 Mandate | M53: Infra Debt | N53: 20372000 | O53: 20372000 | P53: GBP | Q53: Loan | R53: Y | S53: L100209 | T53: Infrastructure Debt | U53: NL | V53: Netherlands | W53: Toll roads | X53: CR1007 | Y53: 11.5 | Z53: EUR | AA53: 1 | AB53: N | AC53: 20759000 | AD53: 20759000 | AE53: 20759000 | AF53: 0.9814 | AG53: 20372000 | AH53: 20372000 | AI53: 387000 | AJ53: 20759000 | AK53: 20372000 | AL53: 20372000 | AN53: 5.736 | AO53: 5.814 | AP53: 5.126 | AQ53: 100 | AR53: 100 | AS53: 45739 | AT53: 51948 | AU53: 46295 | AV53: PI2007 | AW53: Helios Partners | AX53: N | AY53: Harbour Toll Finance Ltd | AZ53: Harbour Toll Finance | BA53: Netherlands | BB53: Helios Partners | BC53: 529900SYNTH000000007 | BI53: 20759000 | BJ53: 20759000 | BK53: Fixed | BL53: Senior Secured | BN53: 10.2 | BO53: 15.73 | BP53: N | BQ53: Y | BR53: Debt | BS53: RA100209 | BT53: D. Schäfer | BU53: D. Schäfer | BW53: Semi-annual | BX53: 30/360 | BY53: 305 | BZ53: 305 | CC53: BBB | CD53: BBB | CE53: NR | CF53: NR | CG53: NR | CH53: 46112 | CI53: 1.2 | CJ53: 2.87 | CK53: 3.01 | CL53: OK | DA53: 0.5 | DC53: 0.85 | DD53: OK | ED53: OK | EE53: 1.05 | EI53: 1.37 | FQ53: 43760510
B54: =C54&"x"&I54 -> 61002x100209 | C54: =IF(G54="SINGLE",H54,G54) -> 61002 | D54: =_xlfn.XLOOKUP(I54,calculations!$t:$t,calculations!$s:$s) -> #VALUE! | E54: =_xlfn.XLOOKUP(I54,Mapping!$T:$T,Mapping!$Q:$Q) -> HARB08 | F54: 46203 | G54: 61002 | H54: 61002 | I54: 100209 | J54: Harbour Toll | K54: Investor 2 Portfolio | L54: Investor 2 Portfolio | M54: Infra Debt | N54: 29139000 | O54: 29139000 | P54: EUR | Q54: Loan | R54: Y | S54: L100209 | T54: Infrastructure Debt | U54: NL | V54: Netherlands | W54: Toll roads | X54: CR1007 | Y54: 11.5 | Z54: EUR | AA54: 1 | AB54: N | AC54: 29692000 | AD54: 29692000 | AE54: 29692000 | AF54: 0.9814 | AG54: 29139000 | AH54: 29139000 | AI54: 553000 | AJ54: 29692000 | AK54: 29139000 | AL54: 29139000 | AN54: 4.927 | AO54: 4.887 | AP54: 5.803 | AQ54: 100 | AR54: 100 | AS54: 45739 | AT54: 51948 | AU54: 46295 | AV54: PI2007 | AW54: Helios Partners | AX54: N | AY54: Harbour Toll Finance Ltd | AZ54: Harbour Toll Finance | BA54: Netherlands | BB54: Helios Partners | BC54: 529900SYNTH000000007 | BI54: 29692000 | BJ54: 29692000 | BK54: Fixed | BL54: Senior Secured | BN54: 10.2 | BO54: 15.73 | BP54: N | BQ54: Y | BR54: Debt | BS54: RA100209 | BT54: D. Schäfer | BU54: C. Dubois | BW54: Quarterly | BX54: ACT/360 | BY54: 305 | BZ54: 305 | CC54: BBB | CD54: BBB | CE54: NR | CF54: NR | CG54: NR | CH54: 46112 | CI54: 1.2 | CJ54: 2.76 | CK54: 2.9 | CL54: OK | DA54: 0.46 | DC54: 0.85 | DD54: OK | ED54: Watch | EE54: 1.05 | EI54: 1.16 | FQ54: 26735204
B55: =C55&"x"&I55 -> 61005x100210 | C55: =IF(G55="SINGLE",H55,G55) -> 61005 | D55: =_xlfn.XLOOKUP(I55,calculations!$t:$t,calculations!$s:$s) -> #VALUE! | E55: =_xlfn.XLOOKUP(I55,Mapping!$T:$T,Mapping!$Q:$Q) -> IRIS09 | F55: 46203 | G55: 61005 | H55: 61005 | I55: 100210 | J55: Iris Fibre | K55: Investor 5 Portfolio | L55: Investor 5 Portfolio | M55: Infra Debt | N55: 24364000 | O55: 28495906 | P55: EUR | Q55: Loan | R55: N | S55: L100210 | T55: Infrastructure Debt | U55: GB | V55: United Kingdom | W55: Fibre networks | X55: CR1008 | Y55: 13.2 | Z55: GBP | AA55: 0.855 | AB55: Y | AC55: 24896000 | AD55: 24896000 | AE55: 29118129 | AF55: 0.9786 | AG55: 24364000 | AH55: 24364000 | AI55: 532000 | AJ55: 24896000 | AK55: 24364000 | AL55: 24364000 | AN55: 4.614 | AO55: 4.45 | AP55: 4.703 | AQ55: 100 | AR55: 100 | AS55: 42538 | AT55: 52034 | AU55: 46295 | AV55: PI2008 | AW55: Northwind Capital | AX55: N | AY55: Iris Fibre Finance Ltd | AZ55: Iris Fibre Finance | BA55: United Kingdom | BB55: Northwind Capital | BC55: 529900SYNTH000000008 | BI55: 24896000 | BJ55: 29118129 | BK55: Fixed | BL55: Senior Secured | BN55: 15.6 | BO55: 15.96 | BP55: N | BQ55: N | BR55: Debt | BS55: RA100210 | BT55: D. Schäfer | BU55: F. Lindqvist | BW55: Quarterly | BX55: ACT/360 | BY55: 245 | BZ55: 245 | CC55: BBB+ | CD55: BBB+ | CE55: NR | CF55: NR | CG55: NR | CH55: 46112 | CI55: 1.2 | CJ55: 2.38 | CK55: 2.5 | CL55: OK | DA55: 0.58 | DC55: 0.85 | DD55: OK | ED55: OK | EE55: 1.05 | EI55: 1.87 | FQ55: 105085150
